Workbook
Name GND_OC_Philosophy: CAP_487V!$A$232
Name GND_OC_Philosophy: HV_351S!#REF!
Name GND_OC_Philosophy: CAP_487V!$A$232
Name GND_OC_Philosophy: CAP_487V!$A$232
Name GND_OC_Philosophy: Reference!#REF!
Name GND_OC_Philosophy: XFMR_487E!#REF!
Name GND_OC_Philosophy: FDR_351S!$A$152
Name GND_TOC_Philosophy: CAP_487V!#REF!
Name GND_TOC_Philosophy: HV_351S!$A$158
Name GND_TOC_Philosophy: CAP_487V!#REF!
Name GND_TOC_Philosophy: CAP_487V!#REF!
Name GND_TOC_Philosophy: Reference!#REF!
Name GND_TOC_Philosophy: XFMR_487E!#REF!
Name GND_TOC_Philosophy: FDR_351S!$A$175
Name pangolin: #REF!
Name PH_OC_Philosophy: CAP_487V!$A$179
Name PH_OC_Philosophy: HV_351S!#REF!
Name PH_OC_Philosophy: CAP_487V!$A$179
Name PH_OC_Philosophy: CAP_487V!$A$179
Name PH_OC_Philosophy: Reference!#REF!
Name PH_OC_Philosophy: XFMR_487E!$A$224
Name PH_OC_Philosophy: FDR_351S!$A$100
Name PH_TOC_Philosophy: CAP_487V!$A$209
Name PH_TOC_Philosophy: HV_351S!$A$115
Name PH_TOC_Philosophy: CAP_487V!$A$209
Name PH_TOC_Philosophy: CAP_487V!$A$209
Name PH_TOC_Philosophy: Reference!#REF!
Name PH_TOC_Philosophy: XFMR_487E!$A$263
Name PH_TOC_Philosophy: FDR_351S!$A$128
Name Port_F: #REF!
Name Vfreq_Philosophy: CAP_487V!$A$252
Name Vfreq_Philosophy: HV_351S!$A$204
Name Vfreq_Philosophy: CAP_487V!$A$252
Name Vfreq_Philosophy: CAP_487V!$A$252
Name Vfreq_Philosophy: Reference!#REF!
Name Vfreq_Philosophy: XFMR_487E!#REF!
Name Vfreq_Philosophy: FDR_351S!$A$201

Sheet Reference
A1: Collector Substation Relay Settings
A7: Project Data
A8: Project | B8: Grover Hill Wind
A9: Client | B9: White Construction/AEP/Lotus
A10: Engineer | B10: T. Clark
A11: Date | B11: 45933
A12: Revision | B12: A
A15: Shared Settings
A16: Terminal/Station ID | B16: GRVR HL WND
A17: Company Name | B17: AEP
A18: UTC Offset | B18: -5
A19: Default Router | B19: =[1]IPs!$B$4 -> 172.31.100.254
A20: Subnet Mask | B20: 255.255.255.0
A21: DNP Client IP 1 | B21: 172.31.100.241
A22: DNP Client IP 2 | B22: 172.31.100.243
A23: PMU Client IP | B23: =[1]IPs!$G$45 -> 172.31.100.38
A26: Change Log
A27: Revision | B27: Date | C27: Description
A28: A | B28: 45933 | C28: Issued for Review

Sheet HV_351S
A1: SEL-351S HV Protection Settings & Logic
A7: Relay Specification
A8: Manufacturer | B8: SEL
A9: Model | B9: SEL-351S
A10: Part # | B10: 0351S7XHD3E5441
A11: Function | B11: HV Protection and Bkr Control
A13: Front View | E13: Rear View
A26: Relay Classification
A27: Relay ID (RID) | B27: Setpoint Class | C27: Logic Class | D27: IP Address (IPADDR)
A28: 11T1 | B28: A | C28: 1 | D28: =IFERROR(VLOOKUP(class_HV351S[[#This Row],[Relay ID (RID)]],[1]IPs!$C$45:$G$250,5,FALSE),"") -> 172.31.100.80
D29: =IFERROR(VLOOKUP(class_HV351S[[#This Row],[Relay ID (RID)]],[1]IPs!$C$45:$G$250,5,FALSE),"")
D30: =IFERROR(VLOOKUP(class_HV351S[[#This Row],[Relay ID (RID)]],[1]IPs!$C$45:$G$250,5,FALSE),"")
D31: =IFERROR(VLOOKUP(class_HV351S[[#This Row],[Relay ID (RID)]],[1]IPs!$C$45:$G$250,5,FALSE),"")
D32: =IFERROR(VLOOKUP(class_HV351S[[#This Row],[Relay ID (RID)]],[1]IPs!$C$45:$G$250,5,FALSE),"")
A35: I/O Summary | D35: Remote Bit Summary
A36: I/O | B36: Description | D36: Element | E36: Description | F36: Behavior
A37: IN101 | B37: 52T1 Status (a) | D37: OC | E37: 52T SCADA Open | F37: Pulse
A38: IN102 | B38: 52T1 Status (b) | D38: CC | E38: 52T SCADA Close | F38: Pulse
A39: IN103 | B39: Not Used | D39: RB1 | E39: Target Reset | F39: Pulse
A40: IN104 | B40: Not Used | D40: RB2 | E40: 89L1 SCADA Open | F40: Pulse
A41: IN105 | B41: 86BFH1 Status | D41: RB3 | E41: 89L1 SCADA Close | F41: Pulse
A42: IN106 | B42: 86BFH1 Trip Coil Monitor
A43: OUT101 | B43: 52T1 Protection Trip (TC1)
A44: OUT102 | B44: 52T1 SCADA Trip | D44: Pushbutton Summary
A45: OUT103 | B45: 52T1 SCADA Close | D45: Element | E45: Description | F45: Target LED
A46: OUT104 | B46: 86BFH1 Lockout Trip | D46: PB1 | E46: Remote Enable | F46: LED1
A47: OUT105 | B47: 11T1 Fault Indicator | D47: PB2 | E47: Undervoltage Disable | F47: LED2
A48: OUT106 | B48: 52T1 Secondary Trip (TC2) | D48: PB3 | E48: Breaker Failure Disable | F48: LED3
A49: OUT107 | B49: 52T1 Block Close | D49: PB4 | E49: Not Used | F49: LED4
A50: ALARM | B50: Relay Fail Alarm to DPAC | D50: PB5 | E50: Operator Lock (hold for 3 sec) | F50: LED5
A51: IN201 | B51: 52T1 Breaker Failure Initiate | D51: PB6 | E51: Trip Coil Failed (push to reset) | F51: LED6
A52: IN202 | B52: 89L1 Status (a) | D52: PB7 | E52: Not Used | F52: LED7
A53: IN203 | B53: 89L1 L/R Status | D53: PB8 | E53: Not Used | F53: LED8
A54: IN204 | B54: 52T1 Loss of Motor DC | D54: PB9 | E54: Not Used | F54: LED9
A55: IN205 | B55: 52T1 Auto Transfer Motor Power | D55: PB10 | E55: Not Used | F55: LED10
A56: IN206 | B56: Not Used
A57: IN207 | B57: 52T1 Spring Alarm
A58: IN208 | B58: 52T1 TCM Trip 1 | D58: Ratios & Nominal Voltages
A59: IN209 | B59: 52T1 TCM Trip 2 | D59: Element | E59: Value
A60: IN210 | B60: 52T1 Low SF6 LO Trip 1 | D60: CT Ratio | E60: 240
...

Sheet XFMR_487E
A1: SEL-487E XFMR Protection Settings & Logic
A7: Relay Specification
A8: Manufacturer | B8: SEL
A9: Model | B9: SEL-487E
A10: Part # | B10: 0487E3X411XXB0X4H644XXX
A11: Function | B11: XFMR Protection
A13: Front View | E13: Rear View
A36: Relay Classification
A37: Relay ID (RID) | B37: Setpoint Class | C37: Logic Class | D37: IP Address/CIDR Prefix (IPADDR)
A38: 87T1P | B38: A | C38: 1 | D38: 172.31.100.81/24
A41: I/O Summary | D41: Remote Bit Summary
A42: I/O | B42: Description | D42: Element | E42: Description | F42: Behavior
A43: IN101 | B43: 52T1 Status (a) | D43: RB01 | E43: Target Reset | F43: Pulse
A44: IN102 | B44: 52T1 Status (b)
A45: IN103 | B45: Not Used
A46: IN104 | B46: 86T1P Status
A47: IN105 | B47: 86T1P Trip Coil Monitor
A48: IN106 | B48: MPT1 Sump Pump Alarm | D48: Pushbutton Summary
A49: IN107 | B49: Not Used | D49: Element | E49: Description | F49: Target LED
A50: OUT101 | B50: 52T1 Protection Trip | D50: PB1 | E50: 86T1P Trip Coil Alarm | F50: PB1_LED
A51: OUT102 | B51: 86T1P Lockout Trip | D51: PB2 | E51: Not Used | F51: PB2_LED
A52: OUT103 | B52: 11T1 Breaker Failure Initiate | D52: PB3 | E52: Not Used | F52: PB3_LED
A53: OUT104 | B53: Not Used | D53: PB4 | E53: Not Used | F53: PB4_LED
A54: OUT105 | B54: Not Used | D54: PB5 | E54: Not Used | F54: PB5_LED
A55: OUT106 | B55: Not Used | D55: PB6 | E55: Not Used | F55: PB6_LED
A56: OUT107 | B56: OLTC Disable | D56: PB7 | E56: Not Used | F56: PB7_LED
A57: OUT108 | B57: Relay Fail Alarm | D57: PB8 | E57: Not Used | F57: PB8_LED
A58: IN201 | B58: Not Used | D58: PB9 | E58: Not Used | F58: PB9_LED
A59: IN202 | B59: Not Used | D59: PB10 | E59: Not Used | F59: PB10LED
A60: IN203 | B60: Not Used | D60: PB11 | E60: Not Used | F60: PB11LED
A61: IN204 | B61: MPT1 ETM-X Oil Alarm | D61: PB12 | E61: Not Used | F61: PB12LED
A62: IN205 | B62: MPT1 26Q-1 Oil Temp alarm
A63: IN206 | B63: MPT1 27-4 UV Alarm (B)
A64: IN207 | B64: MPT1 63PR-X PR Alarm
A65: IN208 | B65: MPT1 63GA-1 Service Alarm
A66: IN209 | B66: MPT1 27-AR Rapid Pressure Alarm
A67: IN210 | B67: MPT1 63SDG Gas Alarm
A68: IN211 | B68: MPT1 PR-4X PR LTC Alarm
A69: IN212 | B69: MPT1 27-X AC Alarm
A70: IN213 | B70: Not Used
...

Sheet XFMR_787
A1: SEL-787 XFMR Protection Settings & Logic
A7: Relay Specification
A8: Manufacturer | B8: SEL
A9: Model | B9: SEL-787
A10: Part # | B10: 07872EE1A1A1A79850620
A11: Function | B11: XFMR Protection
A13: Front View | E13: Rear View
A35: Relay Classification
A36: Relay ID (RID) | B36: Setpoint Class | C36: Logic Class | D36: IP Address (IPADDR)
A37: 87T1S | B37: A | C37: 1 | D37: =IFERROR(VLOOKUP(class_787[[#This Row],[Relay ID (RID)]],[1]IPs!$C$45:$G$250,5,FALSE),"") -> 172.31.100.82
A39: I/O Summary | D39: Remote Bit Summary
A40: I/O | B40: Description | D40: Element | E40: Description | F40: Behavior
A41: IN101 | B41: 52T1 Status (a) | D41: RB01 | E41: Target Reset | F41: Pulse
A42: IN102 | B42: Not Used
A43: OUT101 | B43: 52T1 Secondary Protection Trip
A44: OUT102 | B44: 86T1S Lockout Trip | D44: Pushbutton Summary
A45: OUT103 | B45: Relay Fail Alarm | D45: Element | E45: Description | F45: Target LED
A46: IN301 | B46: Spare | D46: PB1 | E46: 86T1S Trip Coil Failed (push to reset) | F46: PB1A_LED
A47: IN302 | B47: Spare | D47: PB2 | E47: Not Used | F47: PB2A_LED
A48: IN303 | B48: Not Used | D48: PB3 | E48: Not Used | F48: PB3A_LED
A49: IN304 | B49: Not Used | D49: PB4 | E49: Not Used | F49: PB4A_LED
A50: OUT301 | B50: 11T1 Breaker Failure Initiate | D50: PB5 | E50: Not Used | F50: PB5A_LED
A51: OUT302 | B51: Not Used | D51: PB6 | E51: Not Used | F51: PB6A_LED
A52: OUT303 | B52: Not Used | D52: PB7 | E52: Not Used | F52: PB7A_LED
A53: OUT304 | B53: Not Used | D53: PB8 | E53: Not Used | F53: PB8A_LED
A54: IN401 | B54: 86T1S Status
A55: IN402 | B55: 86T1S Trip Coil Monitor
A56: IN403 | B56: Not Used
A57: IN404 | B57: Not Used
A58: OUT401 | B58: Relay Fault Indicator
A59: OUT402 | B59: Not Used
A60: OUT403 | B60: Not Used
A61: OUT404 | B61: Not Used
A64: Ratios & Nominal Voltages | C64: Setpoint Class
A65: Terminal | B65: Element | C65: A | D65: B | E65: C | F65: D | G65: E
A66: W1 | B66: CTR1 | C66: 240
A67: W2 | B67: CTR2 | C67: 600
B68: HV Voltage (kV-LL) | C68: 138
B69: MV Voltage (kV-LL) | C69: 34.5
B70: PTR | C70: Not Used
...

Sheet FDR_351S
A1: SEL-351S Feeder Protection Settings & Logic
A7: Relay Specification
A8: Manufacturer | B8: SEL
A9: Model | B9: SEL-351S
A10: Part # | B10: 0351S7XHD3E5441
A11: Function | B11: Feeder Protection
A13: Front View | E13: Rear View
A26: Relay Classification
A27: Relay ID (RID) | B27: Setpoint Class | C27: Logic Class | D27: IP Address (IPADDR)
A28: 11F1 | B28: A | C28: 1 | D28: =IFERROR(VLOOKUP(class_351S[[#This Row],[Relay ID (RID)]],[1]IPs!$C$45:$G$250,5,FALSE),"") -> 172.31.100.84
A29: 11F2 | B29: B | C29: 2 | D29: =IFERROR(VLOOKUP(class_351S[[#This Row],[Relay ID (RID)]],[1]IPs!$C$45:$G$250,5,FALSE),"") -> 172.31.100.85
A30: 11F3 | B30: B | C30: 2 | D30: =IFERROR(VLOOKUP(class_351S[[#This Row],[Relay ID (RID)]],[1]IPs!$C$45:$G$250,5,FALSE),"") -> 172.31.100.86
A31: 11F4 | B31: B | C31: 2 | D31: =IFERROR(VLOOKUP(class_351S[[#This Row],[Relay ID (RID)]],[1]IPs!$C$45:$G$250,5,FALSE),"") -> 172.31.100.87
A32: 11F5 | B32: B | C32: 2 | D32: =IFERROR(VLOOKUP(class_351S[[#This Row],[Relay ID (RID)]],[1]IPs!$C$45:$G$250,5,FALSE),"") -> 172.31.100.88
A33: 11F6 | B33: B | C33: 2 | D33: =IFERROR(VLOOKUP(class_351S[[#This Row],[Relay ID (RID)]],[1]IPs!$C$45:$G$250,5,FALSE),"") -> 172.31.100.89
A36: I/O Summary | D36: Remote Bit Summary
A37: I/O | B37: Description | D37: Element | E37: Description | F37: Behavior
A38: IN101 | B38: 52F Status (a) | D38: OC | E38: 52F SCADA Open | F38: Pulse
A39: IN102 | B39: 52F Status (b) | D39: CC | E39: 52F SCADA Close | F39: Pulse
A40: IN103 | B40: Not Used | D40: RB1 | E40: Target Reset | F40: Pulse
A41: IN104 | B41: Not Used
A42: IN105 | B42: 86BFL1 Status (F1 Only)
A43: IN106 | B43: 86BFL1 Trip Coil Monitor (F1 Only) | D43: Pushbutton Summary
A44: OUT101 | B44: 52F Protection Trip (TC1) | D44: Element | E44: Description | F44: Target LED
A45: OUT102 | B45: 52F SCADA Trip | D45: PB1 | E45: Remote Enable | F45: LED1
A46: OUT103 | B46: 52F SCADA Close | D46: PB2 | E46: Undervoltage Disable | F46: LED2
A47: OUT104 | B47: 86BFL1 Lockout Trip | D47: PB3 | E47: Breaker Failure Disable | F47: LED3
A48: OUT105 | B48: 11F1 Fault Indicator | D48: PB4 | E48: Breaker Failed (push to reset) | F48: LED4
A49: OUT106 | B49: 52F Secondary Trip (TC2) | D49: PB5 | E49: Operator Lock (hold for 3 sec) | F49: LED5
A50: OUT107 | B50: 52F Block Close | D50: PB6 | E50: Trip Coil Failed (push to reset) | F50: LED6
A51: ALARM | B51: Relay Fail Alarm | D51: PB7 | E51: Maintenance Mode Enable | F51: LED7
A52: IN201 | B52: Not Used | D52: PB8 | E52: Not Used | F52: LED8
A53: IN202 | B53: 52F Loss of AC Heater | D53: PB9 | E53: Not Used | F53: LED9
A54: IN203 | B54: 52F Loss of AC Motor | D54: PB10 | E54: Not Used | F54: LED10
A55: IN204 | B55: 52F Spring Alarm
A56: IN205 | B56: 52F Loss of DC Close
A57: IN206 | B57: 52F Loss of DC T1 | D57: Ratios & Nominal Voltages
A58: IN207 | B58: 52F Loss of DC T2 | D58: Element | E58: Value
A59: IN208 | B59: 52F TCM T1 | D59: CT Ratio | E59: 240
A60: IN209 | B60: 52F TCM T2 | D60: PT Ratio | E60: 300
...

Sheet CAP_487V
A1: SEL-487V Cap Bank Protection Settings & Logic
A7: Relay Specification
A8: Manufacturer | B8: SEL
A9: Model | B9: SEL-487V
A10: Part # | B10: 0487V1X4151XB0X4H5B444X
A11: Function | B11: Cap Bank Protection
A13: Front View | E13: Rear View
A34: Relay Classification
A35: Relay ID (RID) | B35: Setpoint Class | C35: Logic Class | D35: IP Address/CIDR (IPADDR)
A36: 11C1 | B36: A | C36: 2 | D36: 172.31.100.90/24
A39: I/O Summary | D39: Remote Bit Summary
A40: I/O | B40: Description | D40: Element | E40: Description | F40: Behavior
A41: IN101 | B41: 52C1 Status (a) | D41: RB01 | E41: 52C1 Remote Open | F41: Pulse
A42: IN102 | B42: 52C1 Status (b) | D42: RB02 | E42: 52C1 Remote Close | F42: Pulse
A43: IN103 | B43: 86CSW1 TCM | D43: RB03 | E43: CSW1 Auto Open | F43: Pulse
A44: IN104 | B44: 86CSW2 TCM | D44: RB04 | E44: CSW1 Auto Close | F44: Pulse
A45: IN105 | B45: Not Used | D45: RB05 | E45: CSW1 Remote Open | F45: Pulse
A46: IN106 | B46: Not Used | D46: RB06 | E46: CSW1 Remote Close | F46: Pulse
A47: IN107 | B47: Not Used | D47: RB07 | E47: CSW2 Auto Open | F47: Pulse
A48: OUT101 | B48: 52C1 Protection Trip | D48: RB08 | E48: CSW2 Auto Close | F48: Pulse
A49: OUT102 | B49: 52C1 SCADA Trip | D49: RB09 | E49: CSW2 Remote Open | F49: Pulse
A50: OUT103 | B50: 52C1 SCADA Close | D50: RB10 | E50: CSW2 Remote Close | F50: Pulse
A51: OUT104 | B51: 86BFL1 Trip | D51: RB11 | E51: CSW3 Auto Open | F51: Pulse
... A55: OUT108 | B55: Relay Fail Alarm (NC) | D55: RB15 | E55: Target Reset | F55: Pulse
A56: IN201 | B56: 74 DC 52C1 Close
A57: IN202 | B57: 74 DC 52C1 Trip 1
A58: IN203 | B58: 74 DC 52C1 Trip 2 | D58: Pushbutton Summary
A59: IN204 | B59: 52C1 Loss of AC Heater | D59: Element | E59: Description | F59: Target LED
A60: IN205 | B60: 52C1 Loss of AC Motor | D60: PB1 | E60: 52C1 Remote Enable | F60: PB1_LED
A61: IN206 | B61: 52C1 Spring Alarm | D61: PB2 | E61: Undervoltage Disable | F61: PB2_LED
A62: IN207 | B62: 52C1 Loss of DC Close | D62: PB3 | E62: Breaker Failure Disable | F62: PB3_LED
A63: IN208 | B63: 52C1 Loss of DC Trip 1 | D63: PB4 | E63: Breaker Failed (push to reset) | F63: PB4_LED
A64: IN209 | B64: 52C1 Loss of DC Trip 2 | D64: PB5 | E64: Trip Coil Failed (push to reset) | F64: PB5_LED
A65: IN210 | B65: 52C1 Trip 1 TCM | D65: PB6 | E65: Operator Lock (hold to disable) | F65: PB6_LED
A66: IN211 | B66: 52C1 Trip 2 TCM | D66: PB7 | E66: CAP Unbalance Alarm (push to reset) | F66: PB7_LED
A67: IN212 | B67: 52C1 43L/R Indication | D67: PB8 | E67: Auto Control Enable | F67: PB8_LED
A68: IN213 | B68: 74 DC CSW1 Close Circuit | D68: PB9 | E68: CSW1 Auto/Remote Enable | F68: PB9_LED
A69: IN214 | B69: 74 DC CSW1 Trip Circuit | D69: PB10 | E69: CSW2 Auto/Remote Enable | F69: PB10_LED
A70: IN215 | B70: 86CSW1 Status | D70: PB11 | E70: Not Used | F70: PB11_LED
A71: IN216 | B71: CSW1 Status (a) | D71: PB12 | E71: Not Used | F71: PB12_LED
...

Sheet BUS_587Z
A1: SEL-587Z Bus Protection Settings & Logic
A7: Relay Specification
A8: Manufacturer | B8: SEL
A9: Model | B9: SEL-587Z
A10: Part # | B10: 0587Z0X325H12XX
A11: Function | B11: Bus Protection
A13: Front View | E13: Rear View
A26: Relay Classification
A27: Relay ID (RID) | B27: Setpoint Class | C27: Logic Class
A28: 87B | B28: A | C28: 1
A33: I/O Summary
A34: I/O | B34: Description
A35: IN1 | B35: 86B Trip Coil Monitor
A36: IN2 | B36: 86B Status
A37: OUT1 | B37: 86B Lockout Trip
A38: OUT2 | B38: Spare
A39: OUT3 | B39: Not Used
A40: OUT4 | B40: 87B Fault Indicator
A41: ALARM | B41: Relay Fail Alarm
A44: Ratios | C44: Setpoint Class
B45: Element | C45: A | D45: B | E45: C | F45: D | G45: E
B46: CTR | C46: 600
A49: Short Circuit Current Values
A50: Relay | B50: Setpoint Class | C50: Fault Location | D50: 3 PH (A-pri) | E50: SLG (A-pri)
A51: 87B | B51: A | C51: 34.5kV MV1 | D51: 30123 | E51: 17777
A52: 87B2 | B52: B | C52: 34.5kV MV2 | D52: 18763 | E52: 14019
A53: 87B3 | B53: C | C53: 34.5kV MV3 | D53: 30865 | E53: 17850
A56: Diff Voltage Pickup Calculations
A57: Relay | B57: Fault Type | C57: N | D57: Rct | E57: Lead Length | F57: Rlead | G57: If | H57: P | I57: Vr | J57: Vs
A58: 87B | B58: 3Θ | C58: 800 | D58: 1.19 | E58: 510 | F58: 0.612 | G58: 30123 | H58: 1 | I58: =diff_V_587Z[[#This Row],[If]]/diff_V_587Z[[#This Row],[N]]*(diff_V_587Z[[#This Row],[Rct]]+diff_V_587Z[[#This Row],[P]]*diff_V_587Z[[#This Row],[Rlead]]) -> 67.852058 | J58: =1.25*diff_V_587Z[[#This Row],[Vr]] -> 84.815072
A59: 87B | B59: SLG | C59: 800 | D59: 1.19 | E59: 510 | F59: 0.612 | G59: 17777 | H59: 2 | I59: =diff_V_587Z[[#This Row],[If]]/diff_V_587Z[[#This Row],[N]]*(diff_V_587Z[[#This Row],[Rct]]+diff_V_587Z[[#This Row],[P]]*diff_V_587Z[[#This Row],[Rlead]]) -> 53.642097 | J59: =1.25*diff_V_587Z[[#This Row],[Vr]] -> 67.052622
A60: 87B2 | B60: 3Θ | C60: 600 | D60: 0.79 | E60: 913 | F60: 1.096 | G60: 18763 | H60: 1 | I60: =diff_V_587Z[[#This Row],[If]]/diff_V_587Z[[#This Row],[N]]*(diff_V_587Z[[#This Row],[Rct]]+diff_V_587Z[[#This Row],[P]]*diff_V_587Z[[#This Row],[Rlead]]) -> 58.978363 | J60: =1.25*diff_V_587Z[[#This Row],[Vr]] -> 73.722954
A61: 87B2 | B61: SLG | C61: 600 | D61: 0.79 | E61: 913 | F61: 1.096 | G61: 14019 | H61: 2 | I61: =diff_V_587Z[[#This Row],[If]]/diff_V_587Z[[#This Row],[N]]*(diff_V_587Z[[#This Row],[Rct]]+diff_V_587Z[[#This Row],[P]]*diff_V_587Z[[#This Row],[Rlead]]) -> 69.67443 | J61: =1.25*diff_V_587Z[[#This Row],[Vr]] -> 87.093038
A62: 87B3 | B62: 3Θ | C62: 800 | D62: 1.19 | E62: 1052 | F62: 1.262 | G62: 30865 | H62: 1 | I62: =diff_V_587Z[[#This Row],[If]]/diff_V_587Z[[#This Row],[N]]*(diff_V_587Z[[#This Row],[Rct]]+diff_V_587Z[[#This Row],[P]]*diff_V_587Z[[#This Row],[Rlead]]) -> 94.601225 | J62: =1.25*diff_V_587Z[[#This Row],[Vr]] -> 118.25153
A63: 87B3 | B63: SLG | C63: 800 | D63: 1.19 | E63: 1052 | F63: 1.262 | G63: 17850 | H63: 2 | I63: =diff_V_587Z[[#This Row],[If]]/diff_V_587Z[[#This Row],[N]]*(diff_V_587Z[[#This Row],[Rct]]+diff_V_587Z[[#This Row],[P]]*diff_V_587Z[[#This Row],[Rlead]]) -> 82.868625 | J63: =1.25*diff_V_587Z[[#This Row],[Vr]] -> 103.58578
A65: Diff Voltage Calc Philosophy
A66: N = CT ratio Rct = max CT internal resistance Rlead = max CT lead resistance Resistance of #10 AWG = 1.2Ω/1000ft If = Maximum external fault current (max fault at feeders) P = Lead length factor = 1 for three phase faults | 2 for single phase faults Vr = Voltage across high-impedance differential element Vr = (If/N)∗(Rct +P∗Rlead)
A80: 87B Differential Settings | C80: Setpoint Class
A81: Level 1 | C81: A | D81: B | E81: C | F81: D | G81: E
A82: Pickup, A Phase | B82: 87A1P (V-sec) | C82: 200
...

Sheet MTR_735
A1: SEL-735 Meter Settings & Logic
A7: Relay Specification
A8: Manufacturer | B8: SEL
A9: Model | B9: SEL-735
A10: Part # | B10: 0735BX20944CFXB4XX16101XX
A11: Function | B11: Metering
A13: Front View | C13: Side View | E13: Rear View
A34: Relay Classification
A35: Meter ID (MID) | B35: Setpoint Class | C35: Logic Class | D35: IP Address (IPADDR)
A36: REVMTR1 | B36: A | C36: 1 | D36: =IFERROR(VLOOKUP(class_735[[#This Row],[Meter ID (MID)]],[1]IPs!$C$45:$G$250,5,FALSE),"") -> 172.31.100.175
A37: MTR1 | B37: A | C37: 1 | D37: =IFERROR(VLOOKUP(class_735[[#This Row],[Meter ID (MID)]],[1]IPs!$C$45:$G$250,5,FALSE),"") -> 172.31.100.176
A38: MTR2 | B38: B | C38: 1 | D38: =IFERROR(VLOOKUP(class_735[[#This Row],[Meter ID (MID)]],[1]IPs!$C$45:$G$250,5,FALSE),"") -> 172.31.100.177
D39: =IFERROR(VLOOKUP(class_735[[#This Row],[Meter ID (MID)]],[1]IPs!$C$45:$G$250,5,FALSE),"")
A42: I/O Summary
A43: I/O | B43: Description
A44: OUT103 | B44: Meter Alarm to DPAC
A47: Settings Table
A48: Setting | B48: Value | C48: Description | D48: Category | E48: Function | F48: Setpoint Class | G48: Logic Class | H48: Float | I48: QuickSet Group | J48: SER
A49: TID | B49: =Reference!B16 -> GRVR HL WND | C49: Terminal Identifier | D49: Identifier and Scaling | E49: General | H49: FALSE | J49: FALSE
A50: CTR | B50: 40 | C50: CT Ratio | D50: Identifier and Scaling | E50: Ratio | F50: A | H50: FALSE | J50: FALSE
A51: CTR | B51: 500 | C51: CT Ratio | D51: Identifier and Scaling | E51: Ratio | F51: B | H51: FALSE | J51: FALSE
A52: CTR | B52: 240 | C52: CT Ratio | D52: Identifier and Scaling | E52: Ratio | F52: C | H52: FALSE | J52: FALSE
A53: CTR | B53: 240 | C53: CT Ratio | D53: Identifier and Scaling | E53: Ratio | F53: D | H53: FALSE | J53: FALSE
A54: PTR | B54: 700 | C54: PT Ratio | D54: Identifier and Scaling | E54: Ratio | F54: A | H54: FALSE | J54: FALSE
A55: PTR | B55: 175 | C55: PT Ratio | D55: Identifier and Scaling | E55: Ratio | F55: B | H55: FALSE | J55: FALSE
A56: PTR | B56: 175 | C56: PT Ratio | D56: Identifier and Scaling | E56: Ratio | F56: C | H56: FALSE | J56: FALSE
A57: PTR | B57: 175 | C57: PT Ratio | D57: Identifier and Scaling | E57: Ratio | F57: D | H57: FALSE | J57: FALSE
A58: VOLT_SCA | B58: KILO | C58: Voltage Scaling | D58: Identifier and Scaling | E58: General | H58: FALSE | J58: FALSE
A59: POWR_SCA | B59: MEGA | C59: Power and Demand Scaling | D59: Identifier and Scaling | E59: General | H59: FALSE | J59: FALSE
A60: ENRG_SCA | B60: MEGA | C60: Energy Scaling | D60: Identifier and Scaling | E60: General | H60: FALSE | J60: FALSE
A61: UTC_OFF | B61: =Reference!B18 -> -5 | C61: UTC Offset to Local Time | D61: Global | E61: Time | H61: TRUE | J61: FALSE
A62: SRATE | B62: 128 | C62: Waveform Capture Sample Rate (Samples per Cycle) | D62: Events & Logging | E62: Event | H62: FALSE | J62: FALSE
A63: LER | B63: 120 | C63: Event Length (cycles) | D63: Events & Logging | E63: Event | H63: FALSE | J63: FALSE
A64: PRE | B64: 15 | C64: Prefault Length (cycles) | D64: Events & Logging | E64: Event | H64: FALSE | J64: FALSE
A65: EPORT | B65: Y | C65: Enable Port | D65: Communications | E65: Port F | H65: FALSE | I65: PF | J65: FALSE
A66: PROTO | B66: SEL | C66: Port Protocol | D66: Communications | E66: Port F | H66: FALSE | I66: PF | J66: FALSE
A67: SPEED | B67: 19200 | C67: Baud Rate | D67: Communications | E67: Port F | H67: FALSE | I67: PF | J67: FALSE
A68: EPORT | B68: Y | C68: Enable Port | D68: Communications | E68: Port 1 | H68: FALSE | I68: P1 | J68: FALSE
A69: ETELNET | B69: Y | C69: Enable Telnet | D69: Communications | E69: Port 1 | H69: FALSE | I69: P1 | J69: FALSE
A70: EMODBUS | B70: N | C70: Enable Modbus | D70: Communications | E70: Port 1 | H70: FALSE | I70: P1 | J70: FALSE
...

Sheet DPAC_2440
A1: SEL-2440 DPAC Settings & Logic
A7: Relay Specification
A8: Manufacturer | B8: SEL
A9: Model | B9: SEL-2440
A10: Part # | B10: 24402H11A1A11630
A11: Function | B11: DPAC
A13: Front View | E13: Rear View
A23: Relay Classification
A24: Device ID (DID) | B24: Setpoint Class | C24: Logic Class | D24: IP Address (IPADDR)
A25: DPAC1 | B25: A | C25: 1 | D25: =IFERROR(VLOOKUP(class_2440[[#This Row],[Device ID (DID)]],[1]IPs!$C$45:$G$250,5,FALSE),"") -> 172.31.100.120
A26: DPAC2 | B26: A | C26: 2 | D26: =IFERROR(VLOOKUP(class_2440[[#This Row],[Device ID (DID)]],[1]IPs!$C$45:$G$250,5,FALSE),"") -> 172.31.100.121
A29: I/O Summary
A30: I/O | B30: Description
A31: See project schematics.
A34: Settings Table
A35: Setting | B35: Value | C35: Description | D35: Category | E35: Function | F35: Setpoint Class | G35: Logic Class | H35: Float | I35: QuickSet Group | J35: SER
A36: TID | B36: =Reference!B16 -> GRVR HL WND | C36: Terminal ID | D36: General | E36: Device | H36: FALSE | J36: FALSE
A37: OUT101 | B37: SV01T | C37: Not Used | D37: Outputs | E37: Output | H37: FALSE | J37: FALSE
A38: OUT102 | B38: SV02T | C38: Not Used | D38: Outputs | E38: Output | H38: FALSE | J38: FALSE
A39: OUT103 | B39: SV03T | C39: Not Used | D39: Outputs | E39: Output | H39: FALSE | J39: FALSE
A40: OUT104 | B40: SV04T | C40: Not Used | D40: Outputs | E40: Output | H40: FALSE | J40: FALSE
A41: OUT105 | B41: SV05T | C41: Not Used | D41: Outputs | E41: Output | H41: FALSE | J41: FALSE
A42: OUT106 | B42: SV06T | C42: Not Used | D42: Outputs | E42: Output | H42: FALSE | J42: FALSE
A43: OUT107 | B43: SV07T | C43: Not Used | D43: Outputs | E43: Output | H43: FALSE | J43: FALSE
A44: OUT108 | B44: SV08T | C44: Not Used | D44: Outputs | E44: Output | H44: FALSE | J44: FALSE
A45: OUT109 | B45: SV09T | C45: Not Used | D45: Outputs | E45: Output | H45: FALSE | J45: FALSE
A46: OUT110 | B46: SV10T | C46: Not Used | D46: Outputs | E46: Output | H46: FALSE | J46: FALSE
A47: OUT111 | B47: SV11T | C47: Not Used | D47: Outputs | E47: Output | H47: FALSE | J47: FALSE
A48: OUT112 | B48: SV12T | C48: Not Used | D48: Outputs | E48: Output | H48: FALSE | J48: FALSE
... A52: OUT116 | B52: SV16T | C52: Not Used | D52: Outputs | E52: Output | H52: FALSE | J52: FALSE
A53: EPORT | B53: Y | C53: Port Protocol | D53: Communications | E53: Port F | H53: FALSE | I53: PF | J53: FALSE
A54: SPEED | B54: 19200 | C54: Baud Rate | D54: Communications | E54: Port F | H54: FALSE | I54: PF | J54: FALSE
A55: EPORT | B55: Y | C55: Enable Port | D55: Communications | E55: Port 1 | H55: FALSE | I55: P1 | J55: FALSE
A56: ETELNET | B56: Y | C56: Enable Telnet | D56: Communications | E56: Port 1 | H56: FALSE | I56: P1 | J56: FALSE
A57: EFTP | B57: N | C57: Enable FTP | D57: Communications | E57: Port 1 | H57: FALSE | I57: P1 | J57: FALSE
A58: EPING | B58: Y | C58: Enable Ping | D58: Communications | E58: Port 1 | H58: FALSE | I58: P1 | J58: FALSE
A59: SUBNETM | B59: =Reference!B20 -> 255.255.255.0 | C59: Subnet Mask | D59: Communications | E59: Port 1 | H59: FALSE | I59: P1 | J59: FALSE
A60: DEFRTR | B60: =Reference!B19 -> 172.31.100.254 | C60: Default Router Gateway | D60: Communications | E60: Port 1 | H60: FALSE | I60: P1 | J60: FALSE
A61: ETCPKA | B61: Y | C61: Enable TCP Keep-Alive | D61: Communications | E61: Port 1 | H61: FALSE | I61: P1 | J61: FALSE
A62: KAIDLE | B62: 10 | C62: TCP KA Idle Range (sec) | D62: Communications | E62: Port 1 | H62: FALSE | I62: P1 | J62: FALSE
...

Sheet Line_GE L90
A1: SEL-411L Line Protection Settings & Logic
A7: Relay Specification
A8: Manufacturer | B8: GE
A9: Model | B9: GE L90
A10: Part # | B10: L90-TB5-HLH-F8L-H6P-L8L-N6S-S6S-U6D-W7K
A11: Function | B11: Line Protection
A13: Front View | E13: Rear View
A34: Relay Classification
A35: Relay ID (RID) | B35: Setpoint Class | C35: Logic Class | D35: IP Address/CIDR (IPADDR)
A36: 87LP | B36: A | C36: 1 | D36: =IFERROR(VLOOKUP(class_411L65[[#This Row],[Relay ID (RID)]],[1]IPs!$C$45:$G$250,5,FALSE),"") -> 172.31.100.70
A39: I/O Summary | D39: Remote Bit Summary
A40: I/O | B40: Description | D40: Element | E40: Description | F40: Behavior
A41: IN/OUT | B41: Description | D41: RB1 | E41: Target Reset | F41: Pulse
A42: IN201 | B42: 52L Status (a)
A43: IN202 | B43: 89L Status (a)
A44: IN203 | B44: 86DTT Status | D44: Pushbutton Summary
A45: IN204 | B45: 86DTT Trip Coil Monitor | D45: Element | E45: Description | F45: Target LED
A46: IN205 | B46: Incoming BF TT | D46: PB1 | E46: Local 87L BLOCK | F46: PB1_LED
A47: IN206 | B47: Not Used | D47: PB2 | E47: DTT Tx BLOCK | F47: PB2_LED
A48: IN207 | B48: Not Used | D48: PB3 | E48: DTT Rx BLOCK | F48: PB3_LED
A49: IN208 | B49: Not Used | D49: PB4 | E49: 87L TEST MODE | F49: PB4_LED
A50: OUT201 | B50: 52L Protection Trip (TC1) | D50: PB5 | E50: DTT RECVD Indication | F50: PB5_LED
A51: OUT202 | B51: Not Used | D51: PB6 | E51: DTT SENT Indication | F51: PB6_LED
A52: OUT203 | B52: 86DTT Lockout Trip | D52: PB7 | E52: BKR 52L Status (Grn/Open) | F52: PB7_LED
A53: OUT204 | B53: Breaker Failure Initiate | D53: PB8 | E53: SW 89L Status (Grn/Open) | F53: PB8_LED
A54: OUT205 | B54: Not Used | D54: PB9 | E54: REMOTE 87L BLOCK | F54: PB9_LED
A55: OUT206 | B55: Spare | D55: PB10 | E55: REMOTE TERMINAL (Grn/Open) | F55: PB10LED
A56: OUT207 | B56: Not Used | D56: PB11 | E56: 86DTT TCM FAIL (Push to Reset) | F56: PB11LED
A57: OUT208 | B57: Not Used | D57: PB12 | E57: Not Used | F57: PB12LED
A58: OUT209 | B58: Not Used
A59: OUT210 | B59: Not Used
A60: OUT211 | B60: Not Used | D60: Ratios & Nominal Voltages
A61: OUT212 | B61: Not Used | D61: Element | E61: Value
A62: OUT213 | B62: Not Used | D62: CT Ratio | E62: 600
A63: OUT214 | B63: Relay Fail Alarm | D63: PT Ratio | E63: 2000
A64: OUT215 | B64: Not Used | D64: Collector Voltage (LL, kV) | E64: 230
A65: IN301 | B65: Not Used | D65: Relay Nominal Voltage (LL, Vsec) | E65: =E64*10^3/E63 -> 115
A66: IN302 | B66: Not Used
A67: IN303 | B67: Not Used
A68: IN304 | B68: Not Used
...

Sheet Line_411L
A1: SEL-411L Line Protection Settings & Logic
A7: Relay Specification
A8: Manufacturer | B8: SEL
A9: Model | B9: SEL-411L
A10: Part # | B10: 0411L1X6X5C8EEXH674740X
A11: Function | B11: Line Protection
A13: Front View | E13: Rear View
A34: Relay Classification
A35: Relay ID (RID) | B35: Setpoint Class | C35: Logic Class | D35: IP Address/CIDR (IPADDR)
A36: 87LS | B36: A | C36: 1 | D36: =IFERROR(VLOOKUP(class_411L[[#This Row],[Relay ID (RID)]],[1]IPs!$C$45:$G$250,5,FALSE)&"/24","") -> 172.31.100.71/24
A39: I/O Summary | D39: Remote Bit Summary
A40: I/O | B40: Description | D40: Element | E40: Description | F40: Behavior
A41: IN/OUT | B41: Description | D41: RB1 | E41: Target Reset | F41: Pulse
A42: IN201 | B42: 52T Status (a)
A43: IN202 | B43: 89L Status (a)
A44: IN203 | B44: 86DTT Status | D44: Pushbutton Summary
A45: IN204 | B45: Spare | D45: Element | E45: Description | F45: Target LED
A46: IN205 | B46: Incoming BF TT | D46: PB1 | E46: Local 87L BLOCK | F46: PB1_LED
A47: IN206 | B47: Spare | D47: PB2 | E47: DTT Tx BLOCK | F47: PB2_LED
A48: IN207 | B48: Not Used | D48: PB3 | E48: DTT Rx BLOCK | F48: PB3_LED
A49: IN208 | B49: Not Used | D49: PB4 | E49: 87L TEST MODE | F49: PB4_LED
A50: OUT201 | B50: 52T Protection Trip (TC1) | D50: PB5 | E50: DTT Received Indication | F50: PB5_LED
A51: OUT202 | B51: Not Used | D51: PB6 | E51: DTT Sent Indication | F51: PB6_LED
A52: OUT203 | B52: 86DTT Lockout Trip | D52: PB7 | E52: BKR 52T1 Status (Grn/Open) | F52: PB7_LED
A53: OUT204 | B53: Breaker Failure Initiate | D53: PB8 | E53: SW 89L1 Status (Grn/Open) | F53: PB8_LED
A54: OUT205 | B54: Not Used | D54: PB9 | E54: Remote 87L Block | F54: PB9_LED
A55: OUT206 | B55: Spare | D55: PB10 | E55: Remote Terminal Closed | F55: PB10LED
A56: OUT207 | B56: Not Used | D56: PB11 | E56: Remote Terminal Open | F56: PB11LED
A57: OUT208 | B57: Not Used | D57: PB12 | E57: Event Manual Trigger | F57: PB12LED
A58: OUT209 | B58: Not Used
A59: OUT210 | B59: Not Used
A60: OUT211 | B60: Not Used | D60: Ratios & Nominal Voltages
A61: OUT212 | B61: Not Used | D61: Terminal | E61: Element | F61: Value
A62: OUT213 | B62: Not Used | D62: IW | E62: CT Ratio | F62: 400
A63: OUT214 | B63: Relay Fail Alarm | E63: Line Voltage (kV-LL)
A64: OUT215 | B64: Not Used | D64: VY | E64: PT Ratio | F64: 1200
A65: IN301 | B65: Not Used | E65: Line Voltage (LL, kV) | F65: 138
A66: IN302 | B66: Not Used | E66: Relay Nominal Voltage (LL, Vsec) | F66: =F65*10^3/F64 -> 115
A67: IN303 | B67: Not Used
A68: IN304 | B68: Not Used
...

Sheet DFR_TESLA 4000-A
A1: DFR ERLPhase Tesla 4000-A Settings & Logic
A7: Relay Specification
A8: Manufacturer | B8: ERL Phase Power Technologies
A9: Model | B9: TESLA 4000-A
A10: Part # | B10: A2-16-0-0-2-60-0-0-0-0-A
A11: Function | B11: Digital Fault Recorder
A13: Front View | E13: Rear View
A23: Relay Classification
A24: Device ID (DID) | B24: Setpoint Class | C24: Logic Class | D24: IP Address (IPADDR)
A25: DFR1 | B25: A | C25: 1 | D25: =IFERROR(VLOOKUP(class_2440111[[#This Row],[Device ID (DID)]],[1]IPs!$C$45:$G$250,5,FALSE),"") -> 172.31.100.122
D26: =IFERROR(VLOOKUP(class_2440111[[#This Row],[Device ID (DID)]],[1]IPs!$C$45:$G$250,5,FALSE),"")
A29: I/O Summary
A30: I/O | B30: Description
A31: See project schematics.
A34: Settings Table
A35: Setting | B35: Value | C35: Description | D35: Category | E35: Function | F35: Setpoint Class | G35: Logic Class | H35: Float | I35: QuickSet Group | J35: SER
A36: TID | B36: =Reference!B16 -> GRVR HL WND | C36: Terminal ID | D36: General | E36: Device | H36: FALSE | J36: FALSE
A37: OUT101 | B37: SV01T | C37: Not Used | D37: Outputs | E37: Output | H37: FALSE | J37: FALSE
A38: OUT102 | B38: SV02T | C38: Not Used | D38: Outputs | E38: Output | H38: FALSE | J38: FALSE
A39: OUT103 | B39: SV03T | C39: Not Used | D39: Outputs | E39: Output | H39: FALSE | J39: FALSE
A40: OUT104 | B40: SV04T | C40: Not Used | D40: Outputs | E40: Output | H40: FALSE | J40: FALSE
A41: OUT105 | B41: SV05T | C41: Not Used | D41: Outputs | E41: Output | H41: FALSE | J41: FALSE
A42: OUT106 | B42: SV06T | C42: Not Used | D42: Outputs | E42: Output | H42: FALSE | J42: FALSE
A43: OUT107 | B43: SV07T | C43: Not Used | D43: Outputs | E43: Output | H43: FALSE | J43: FALSE
A44: OUT108 | B44: SV08T | C44: Not Used | D44: Outputs | E44: Output | H44: FALSE | J44: FALSE
A45: OUT109 | B45: SV09T | C45: Not Used | D45: Outputs | E45: Output | H45: FALSE | J45: FALSE
A46: OUT110 | B46: SV10T | C46: Not Used | D46: Outputs | E46: Output | H46: FALSE | J46: FALSE
A47: OUT111 | B47: SV11T | C47: Not Used | D47: Outputs | E47: Output | H47: FALSE | J47: FALSE
A48: OUT112 | B48: SV12T | C48: Not Used | D48: Outputs | E48: Output | H48: FALSE | J48: FALSE
... A53: EPORT | B53: Y | C53: Port Protocol | D53: Communications | E53: Port F | H53: FALSE | J53: FALSE
A54: SPEED | B54: 19200 | C54: Baud Rate | D54: Communications | E54: Port F | H54: FALSE | J54: FALSE
A55: EPORT | B55: Y | C55: Enable Port | D55: Communications | E55: Port 1 | H55: FALSE | J55: FALSE
A56: ETELNET | B56: Y | C56: Enable Telnet | D56: Communications | E56: Port 1 | H56: FALSE | J56: FALSE
A57: EFTP | B57: Y | C57: Enable FTP | D57: Communications | E57: Port 1 | H57: FALSE | J57: FALSE
A58: EPING | B58: Y | C58: Enable Ping | D58: Communications | E58: Port 1 | H58: FALSE | J58: FALSE
A59: SUBNETM | B59: =Reference!B20 -> 255.255.255.0 | C59: Subnet Mask | D59: Communications | E59: Port 1 | H59: FALSE | J59: FALSE
A60: DEFRTR | B60: =Reference!B19 -> 172.31.100.254 | C60: Default Router Gateway | D60: Communications | E60: Port 1 | H60: FALSE | J60: FALSE
A61: TPORT | B61: 23 | C61: Telnet Port | D61: Communications | E61: Port 1 | H61: FALSE | J61: FALSE
A62: NETMODE | B62: FAILOVER | C62: Port Operating Mode | D62: Communications | E62: Port 1 | H62: FALSE | J62: FALSE
A63: NETPORT | B63: A | C63: Primary Port | D63: Communications | E63: Port 1 | H63: FALSE | J63: FALSE
...
